{"type":"l2update","product_id":"BTC-USD","changes":[["sell","54407.14","0.05000000"]],"time":"2021-04-28T15:27:02.638954Z"}
{"type":"l2update","product_id":"BTC-USD","changes":[["sell","55000.00","11.36544164"]],"time":"2021-04-28T15:27:02.671702Z"}
{"type":"l2update","product_id":"BTC-USD","changes":[["buy","54372.76","2.42831647"]],"time":"2021-04-28T15:27:02.693160Z"}
{"type":"l2update","product_id":"BTC-USD","changes":[["sell","54531.58","0.00000000"]],"time":"2021-04-28T15:27:02.721425Z"}
{"type":"l2update","product_id":"BTC-USD","changes":[["sell","54382.30","0.00000000"]],"time":"2021-04-28T15:27:02.733835Z"}
{"type":"l2update","product_id":"BTC-USD","changes":[["buy","54360.47","0.00000000"]],"time":"2021-04-28T15:27:02.733858Z"}
{"type":"l2update","product_id":"BTC-USD","changes":[["sell","54548.68","0.01000000"]],"time":"2021-04-28T15:27:02.734832Z"}
{"type":"l2update","product_id":"BTC-USD","changes":[["buy","54372.76","2.47831647"]],"time":"2021-04-28T15:27:02.751487Z"}
{"type":"l2update","product_id":"BTC-USD","changes":[["buy","54362.42","0.00000000"]],"time":"2021-04-28T15:27:02.770379Z"}
{"type":"l2update","product_id":"BTC-USD","changes":[["sell","54407.15","0.00000000"]],"time":"2021-04-28T15:27:02.773050Z"}
{"type":"l2update","product_id":"BTC-USD","changes":[["buy","54362.43","0.00000000"]],"time":"2021-04-28T15:27:02.778608Z"}
{"type":"l2update","product_id":"BTC-USD","changes":[["buy","54372.76","2.30831647"]],"time":"2021-04-28T15:27:02.786695Z"}
{"type":"l2update","product_id":"BTC-USD","changes":[["buy","54360.31","0.30000000"]],"time":"2021-04-28T15:27:02.790704Z"}
{"type":"l2update","product_id":"BTC-USD","changes":[["buy","54169.96","0.00000000"]],"time":"2021-04-28T15:27:02.814615Z"}
{"type":"l2update","product_id":"BTC-USD","changes":[["buy","54139.47","0.01000000"]],"time":"2021-04-28T15:27:02.826453Z"}
{"type":"l2update","product_id":"BTC-USD","changes":[["sell","54404.03","0.00000000"]],"time":"2021-04-28T15:27:02.834077Z"}
{"type":"l2update","product_id":"BTC-USD","changes":[["buy","54010.03","0.00000000"]],"time":"2021-04-28T15:27:02.843072Z"}
{"type":"l2update","product_id":"BTC-USD","changes":[["buy","54332.67","0.71874000"]],"time":"2021-04-28T15:27:02.844024Z"}
{"type":"l2update","product_id":"BTC-USD","changes":[["buy","54028.52","0.01000000"]],"time":"2021-04-28T15:27:02.852300Z"}
{"type":"l2update","product_id":"BTC-USD","changes":[["buy","54362.37","0.51340000"]],"time":"2021-04-28T15:27:02.860544Z"}
{"type":"l2update","product_id":"BTC-USD","changes":[["buy","54372.76","2.31139054"]],"time":"2021-04-28T15:27:02.866103Z"}
{"type":"l2update","product_id":"BTC-USD","changes":[["sell","54407.11","0.45430000"]],"time":"2021-04-28T15:27:02.869140Z"}
{"type":"l2update","product_id":"BTC-USD","changes":[["sell","54430.53","0.08000000"]],"time":"2021-04-28T15:27:02.873291Z"}
{"type":"l2update","product_id":"BTC-USD","changes":[["sell","54430.53","0.05000000"]],"time":"2021-04-28T15:27:02.876469Z"}
{"type":"l2update","product_id":"BTC-USD","changes":[["sell","54372.77","0.96765469"]],"time":"2021-04-28T15:27:02.878097Z"}
{"type":"l2update","product_id":"BTC-USD","changes":[["sell","54407.14","0.00000000"]],"time":"2021-04-28T15:27:02.878498Z"}
{"type":"l2update","product_id":"BTC-USD","changes":[["sell","54430.53","0.01000000"]],"time":"2021-04-28T15:27:02.879819Z"}
{"type":"l2update","product_id":"BTC-USD","changes":[["buy","54028.52","0.00000000"]],"time":"2021-04-28T15:27:02.887840Z"}
{"type":"l2update","product_id":"BTC-USD","changes":[["sell","54439.97","0.02000000"]],"time":"2021-04-28T15:27:02.891733Z"}
{"type":"l2update","product_id":"BTC-USD","changes":[["buy","54372.76","2.52139054"]],"time":"2021-04-28T15:27:02.892199Z"}
{"type":"l2update","product_id":"BTC-USD","changes":[["sell","54407.10","0.05000000"]],"time":"2021-04-28T15:27:02.892246Z"}
{"type":"l2update","product_id":"BTC-USD","changes":[["buy","54010.03","0.09257538"]],"time":"2021-04-28T15:27:02.899474Z"}
{"type":"l2update","product_id":"BTC-USD","changes":[["sell","54442.08","0.03000000"]],"time":"2021-04-28T15:27:02.902502Z"}
{"type":"l2update","product_id":"BTC-USD","changes":[["sell","54442.50","0.04000000"]],"time":"2021-04-28T15:27:02.911748Z"}
{"type":"l2update","product_id":"BTC-USD","changes":[["buy","54139.47","0.00000000"]],"time":"2021-04-28T15:27:02.920881Z"}
{"type":"l2update","product_id":"BTC-USD","changes":[["sell","54399.95","0.09100000"]],"time":"2021-04-28T15:27:02.924160Z"}
{"type":"l2update","product_id":"BTC-USD","changes":[["buy","54157.12","0.01119600"]],"time":"2021-04-28T15:27:02.931174Z"}
{"type":"l2update","product_id":"BTC-USD","changes":[["sell","54430.53","0.00000000"]],"time":"2021-04-28T15:27:02.932274Z"}
{"type":"l2update","product_id":"BTC-USD","changes":[["sell","54381.99","0.00000000"]],"time":"2021-04-28T15:27:02.933340Z"}
{"type":"l2update","product_id":"BTC-USD","changes":[["sell","54394.72","0.00000000"]],"time":"2021-04-28T15:27:02.939423Z"}
{"type":"l2update","product_id":"BTC-USD","changes":[["buy","54367.86","0.00000000"]],"time":"2021-04-28T15:27:02.941276Z"}
{"type":"l2update","product_id":"BTC-USD","changes":[["buy","54366.64","0.00000000"]],"time":"2021-04-28T15:27:02.941276Z"}
{"type":"l2update","product_id":"BTC-USD","changes":[["sell","54413.37","0.00000000"]],"time":"2021-04-28T15:27:02.942701Z"}
{"type":"l2update","product_id":"BTC-USD","changes":[["sell","54440.34","0.01000000"]],"time":"2021-04-28T15:27:02.943721Z"}
{"type":"l2update","product_id":"BTC-USD","changes":[["sell","54400.92","0.00000000"]],"time":"2021-04-28T15:27:02.945735Z"}
{"type":"l2update","product_id":"BTC-USD","changes":[["sell","54403.62","0.00000000"]],"time":"2021-04-28T15:27:02.946462Z"}
{"type":"l2update","product_id":"BTC-USD","changes":[["sell","54384.80","0.37000000"]],"time":"2021-04-28T15:27:02.947278Z"}
{"type":"l2update","product_id":"BTC-USD","changes":[["sell","54385.87","0.00000000"]],"time":"2021-04-28T15:27:02.952385Z"}
{"type":"l2update","product_id":"BTC-USD","changes":[["buy","54370.34","0.01690000"]],"time":"2021-04-28T15:27:02.959736Z"}
{"type":"l2update","product_id":"BTC-USD","changes":[["buy","54369.53","0.01690000"]],"time":"2021-04-28T15:27:02.959736Z"}
{"type":"l2update","product_id":"BTC-USD","changes":[["sell","54384.80","0.00000000"]],"time":"2021-04-28T15:27:02.965925Z"}
{"type":"l2update","product_id":"BTC-USD","changes":[["sell","54385.76","0.37000000"]],"time":"2021-04-28T15:27:02.970652Z"}
{"type":"l2update","product_id":"BTC-USD","changes":[["sell","54405.30","0.01690000"]],"time":"2021-04-28T15:27:02.970820Z"}
{"type":"l2update","product_id":"BTC-USD","changes":[["buy","54340.46","0.00000000"]],"time":"2021-04-28T15:27:02.973140Z"}
{"type":"l2update","product_id":"BTC-USD","changes":[["sell","54415.79","0.00000000"]],"time":"2021-04-28T15:27:02.973651Z"}
{"type":"l2update","product_id":"BTC-USD","changes":[["sell","54393.57","0.00000000"]],"time":"2021-04-28T15:27:02.975733Z"}
{"type":"l2update","product_id":"BTC-USD","changes":[["buy","54340.42","0.03000000"]],"time":"2021-04-28T15:27:02.975973Z"}
{"type":"l2update","product_id":"BTC-USD","changes":[["buy","54340.42","0.00000000"]],"time":"2021-04-28T15:27:02.980237Z"}
{"type":"l2update","product_id":"BTC-USD","changes":[["buy","54340.29","0.00000000"]],"time":"2021-04-28T15:27:02.983079Z"}
{"type":"l2update","product_id":"BTC-USD","changes":[["sell","54394.76","0.25477024"]],"time":"2021-04-28T15:27:02.986385Z"}
{"type":"l2update","product_id":"BTC-USD","changes":[["sell","54437.39","0.00000000"]],"time":"2021-04-28T15:27:02.988332Z"}
{"type":"l2update","product_id":"BTC-USD","changes":[["buy","54349.15","0.01000000"]],"time":"2021-04-28T15:27:02.994445Z"}
{"type":"l2update","product_id":"BTC-USD","changes":[["buy","54367.18","0.10000000"]],"time":"2021-04-28T15:27:02.998707Z"}
{"type":"l2update","product_id":"BTC-USD","changes":[["buy","54349.12","0.02000000"]],"time":"2021-04-28T15:27:03.002785Z"}
{"type":"l2update","product_id":"BTC-USD","changes":[["buy","54182.82","0.00000000"]],"time":"2021-04-28T15:27:03.005662Z"}
{"type":"l2update","product_id":"BTC-USD","changes":[["sell","54403.72","0.08000000"]],"time":"2021-04-28T15:27:03.013345Z"}
{"type":"l2update","product_id":"BTC-USD","changes":[["buy","54349.12","0.05000000"]],"time":"2021-04-28T15:27:03.013630Z"}
{"type":"l2update","product_id":"BTC-USD","changes":[["sell","54394.11","0.36771671"]],"time":"2021-04-28T15:27:03.014076Z"}
{"type":"l2update","product_id":"BTC-USD","changes":[["buy","54199.83","0.01845024"]],"time":"2021-04-28T15:27:03.018164Z"}
{"type":"l2update","product_id":"BTC-USD","changes":[["buy","54349.12","0.09000000"]],"time":"2021-04-28T15:27:03.024174Z"}
{"type":"l2update","product_id":"BTC-USD","changes":[["sell","54498.18","0.00000000"]],"time":"2021-04-28T15:27:03.024746Z"}
{"type":"l2update","product_id":"BTC-USD","changes":[["buy","54371.40","0.36776962"]],"time":"2021-04-28T15:27:03.025727Z"}
{"type":"l2update","product_id":"BTC-USD","changes":[["sell","54525.40","0.00000000"]],"time":"2021-04-28T15:27:03.032550Z"}
{"type":"l2update","product_id":"BTC-USD","changes":[["buy","54363.04","0.52460000"]],"time":"2021-04-28T15:27:03.036227Z"}
{"type":"l2update","product_id":"BTC-USD","changes":[["sell","54571.89","0.00000000"]],"time":"2021-04-28T15:27:03.038148Z"}
{"type":"l2update","product_id":"BTC-USD","changes":[["sell","54516.77","0.01000000"]],"time":"2021-04-28T15:27:03.038963Z"}
{"type":"l2update","product_id":"BTC-USD","changes":[["buy","54360.29","0.00000000"]],"time":"2021-04-28T15:27:03.039090Z"}
{"type":"l2update","product_id":"BTC-USD","changes":[["sell","54399.55","0.36771671"]],"time":"2021-04-28T15:27:03.039257Z"}
{"type":"l2update","product_id":"BTC-USD","changes":[["sell","54543.10","0.01000000"]],"time":"2021-04-28T15:27:03.042272Z"}
{"type":"l2update","product_id":"BTC-USD","changes":[["buy","54370.37","0.36774008"]],"time":"2021-04-28T15:27:03.050471Z"}
{"type":"l2update","product_id":"BTC-USD","changes":[["sell","54407.45","0.00000000"]],"time":"2021-04-28T15:27:03.057136Z"}
{"type":"l2update","product_id":"BTC-USD","changes":[["sell","54551.35","0.01000000"]],"time":"2021-04-28T15:27:03.058931Z"}
{"type":"l2update","product_id":"BTC-USD","changes":[["sell","54467.64","0.00000000"]],"time":"2021-04-28T15:27:03.062769Z"}
{"type":"l2update","product_id":"BTC-USD","changes":[["sell","54421.59","0.91938020"]],"time":"2021-04-28T15:27:03.063860Z"}
{"type":"l2update","product_id":"BTC-USD","changes":[["sell","54516.77","0.00000000"]],"time":"2021-04-28T15:27:03.068818Z"}
{"type":"l2update","product_id":"BTC-USD","changes":[["sell","54547.57","0.00000000"]],"time":"2021-04-28T15:27:03.069600Z"}
{"type":"l2update","product_id":"BTC-USD","changes":[["sell","54485.39","0.03726000"]],"time":"2021-04-28T15:27:03.071517Z"}
{"type":"l2update","product_id":"BTC-USD","changes":[["sell","54437.39","0.01839070"]],"time":"2021-04-28T15:27:03.074805Z"}
{"type":"l2update","product_id":"BTC-USD","changes":[["buy","54365.97","0.36776962"]],"time":"2021-04-28T15:27:03.075183Z"}
{"type":"l2update","product_id":"BTC-USD","changes":[["sell","54528.49","0.00916951"]],"time":"2021-04-28T15:27:03.080246Z"}
{"type":"l2update","product_id":"BTC-USD","changes":[["sell","54455.76","1.83870036"]],"time":"2021-04-28T15:27:03.087812Z"}
{"type":"l2update","product_id":"BTC-USD","changes":[["sell","54483.07","0.01000000"]],"time":"2021-04-28T15:27:03.095534Z"}
{"type":"l2update","product_id":"BTC-USD","changes":[["buy","54272.38","0.00000000"]],"time":"2021-04-28T15:27:03.099195Z"}
{"type":"l2update","product_id":"BTC-USD","changes":[["buy","54358.00","0.55157154"]],"time":"2021-04-28T15:27:03.099575Z"}
{"type":"l2update","product_id":"BTC-USD","changes":[["sell","54400.77","0.00000000"]],"time":"2021-04-28T15:27:03.100913Z"}
{"type":"l2update","product_id":"BTC-USD","changes":[["buy","54346.51","0.91929178"]],"time":"2021-04-28T15:27:03.113883Z"}
{"type":"l2update","product_id":"BTC-USD","changes":[["buy","54372.76","1.22139054"]],"time":"2021-04-28T15:27:03.117155Z"}
{"type":"l2update","product_id":"BTC-USD","changes":[["buy","54256.74","0.01780900"]],"time":"2021-04-28T15:27:03.119580Z"}
{"type":"l2update","product_id":"BTC-USD","changes":[["sell","54403.99","0.09190502"]],"time":"2021-04-28T15:27:03.120560Z"}
{"type":"l2update","product_id":"BTC-USD","changes":[["buy","54319.45","1.83876039"]],"time":"2021-04-28T15:27:03.123754Z"}
{"type":"l2update","product_id":"BTC-USD","changes":[["buy","54321.05","0.00000000"]],"time":"2021-04-28T15:27:03.128998Z"}
{"type":"l2update","product_id":"BTC-USD","changes":[["buy","54325.04","0.10000000"]],"time":"2021-04-28T15:27:03.141511Z"}
{"type":"l2update","product_id":"BTC-USD","changes":[["buy","54372.76","2.52139054"]],"time":"2021-04-28T15:27:03.163887Z"}
{"type":"l2update","product_id":"BTC-USD","changes":[["sell","54407.11","0.00000000"]],"time":"2021-04-28T15:27:03.164791Z"}
{"type":"l2update","product_id":"BTC-USD","changes":[["sell","54403.99","0.00000000"]],"time":"2021-04-28T15:27:03.165652Z"}
{"type":"l2update","product_id":"BTC-USD","changes":[["buy","54362.37","0.00000000"]],"time":"2021-04-28T15:27:03.168871Z"}
{"type":"l2update","product_id":"BTC-USD","changes":[["sell","54420.91","0.00000000"]],"time":"2021-04-28T15:27:03.171545Z"}
{"type":"l2update","product_id":"BTC-USD","changes":[["buy","54367.83","0.52990000"]],"time":"2021-04-28T15:27:03.180090Z"}
{"type":"l2update","product_id":"BTC-USD","changes":[["sell","54405.94","0.09190173"]],"time":"2021-04-28T15:27:03.180331Z"}
{"type":"l2update","product_id":"BTC-USD","changes":[["buy","54367.83","0.00000000"]],"time":"2021-04-28T15:27:03.183883Z"}
{"type":"l2update","product_id":"BTC-USD","changes":[["sell","54397.73","0.00000000"]],"time":"2021-04-28T15:27:03.183906Z"}
{"type":"l2update","product_id":"BTC-USD","changes":[["sell","54399.95","0.00000000"]],"time":"2021-04-28T15:27:03.185897Z"}
{"type":"l2update","product_id":"BTC-USD","changes":[["sell","54399.99","0.00000000"]],"time":"2021-04-28T15:27:03.188365Z"}
{"type":"l2update","product_id":"BTC-USD","changes":[["sell","54421.79","0.00960143"]],"time":"2021-04-28T15:27:03.244296Z"}
{"type":"l2update","product_id":"BTC-USD","changes":[["sell","54917.19","0.00000000"]],"time":"2021-04-28T15:27:03.252638Z"}
{"type":"l2update","product_id":"BTC-USD","changes":[["sell","54394.11","0.00000000"]],"time":"2021-04-28T15:27:03.254218Z"}
{"type":"l2update","product_id":"BTC-USD","changes":[["sell","54437.39","0.00000000"]],"time":"2021-04-28T15:27:03.254249Z"}
{"type":"l2update","product_id":"BTC-USD","changes":[["buy","54360.31","0.00000000"]],"time":"2021-04-28T15:27:03.257039Z"}
{"type":"l2update","product_id":"BTC-USD","changes":[["buy","54284.02","0.00000000"]],"time":"2021-04-28T15:27:03.258336Z"}
{"type":"l2update","product_id":"BTC-USD","changes":[["sell","54455.28","0.00000000"]],"time":"2021-04-28T15:27:03.258616Z"}
{"type":"l2update","product_id":"BTC-USD","changes":[["buy","54365.97","0.00000000"]],"time":"2021-04-28T15:27:03.259939Z"}
{"type":"l2update","product_id":"BTC-USD","changes":[["sell","54411.22","0.49300000"]],"time":"2021-04-28T15:27:03.265898Z"}
{"type":"l2update","product_id":"BTC-USD","changes":[["buy","54372.51","0.30000000"]],"time":"2021-04-28T15:27:03.271317Z"}
{"type":"l2update","product_id":"BTC-USD","changes":[["buy","54368.26","0.53080000"]],"time":"2021-04-28T15:27:03.274461Z"}
{"type":"l2update","product_id":"BTC-USD","changes":[["buy","54293.74","0.89400032"]],"time":"2021-04-28T15:27:03.278995Z"}
{"type":"l2update","product_id":"BTC-USD","changes":[["sell","54465.03","0.81000000"]],"time":"2021-04-28T15:27:03.279515Z"}
{"type":"l2update","product_id":"BTC-USD","changes":[["sell","54372.77","0.85505469"]],"time":"2021-04-28T15:27:03.295301Z"}
{"type":"l2update","product_id":"BTC-USD","changes":[["sell","54385.76","0.00000000"]],"time":"2021-04-28T15:27:03.305138Z"}
{"type":"l2update","product_id":"BTC-USD","changes":[["sell","54386.29","0.37000000"]],"time":"2021-04-28T15:27:03.310217Z"}
{"type":"l2update","product_id":"BTC-USD","changes":[["sell","54372.77","0.24232779"]],"time":"2021-04-28T15:27:03.313358Z"}
{"type":"l2update","product_id":"BTC-USD","changes":[["buy","54328.51","0.00000000"]],"time":"2021-04-28T15:27:03.315252Z"}
{"type":"l2update","product_id":"BTC-USD","changes":[["buy","54369.53","0.00000000"]],"time":"2021-04-28T15:27:03.320317Z"}
{"type":"l2update","product_id":"BTC-USD","changes":[["buy","54368.66","0.00000000"]],"time":"2021-04-28T15:27:03.320317Z"}
{"type":"l2update","product_id":"BTC-USD","changes":[["buy","54372.51","0.00000000"]],"time":"2021-04-28T15:27:03.322802Z"}
{"type":"l2update","product_id":"BTC-USD","changes":[["sell","54405.30","0.00000000"]],"time":"2021-04-28T15:27:03.325574Z"}
{"type":"l2update","product_id":"BTC-USD","changes":[["buy","54372.76","2.56564054"]],"time":"2021-04-28T15:27:03.326018Z"}
{"type":"l2update","product_id":"BTC-USD","changes":[["buy","54372.76","2.48564054"]],"time":"2021-04-28T15:27:03.326677Z"}
{"type":"l2update","product_id":"BTC-USD","changes":[["sell","54446.10","0.19000000"]],"time":"2021-04-28T15:27:03.330298Z"}
{"type":"l2update","product_id":"BTC-USD","changes":[["sell","54403.72","0.00000000"]],"time":"2021-04-28T15:27:03.330654Z"}
{"type":"l2update","product_id":"BTC-USD","changes":[["sell","54405.94","0.00000000"]],"time":"2021-04-28T15:27:03.331351Z"}
{"type":"l2update","product_id":"BTC-USD","changes":[["buy","54370.62","0.30000000"]],"time":"2021-04-28T15:27:03.333735Z"}
{"type":"l2update","product_id":"BTC-USD","changes":[["buy","54371.95","0.01690000"]],"time":"2021-04-28T15:27:03.337443Z"}
{"type":"l2update","product_id":"BTC-USD","changes":[["buy","54371.14","0.01690000"]],"time":"2021-04-28T15:27:03.337443Z"}
{"type":"l2update","product_id":"BTC-USD","changes":[["sell","54917.15","0.00000000"]],"time":"2021-04-28T15:27:03.342847Z"}
{"type":"l2update","product_id":"BTC-USD","changes":[["buy","54372.76","2.56564054"]],"time":"2021-04-28T15:27:03.345472Z"}
{"type":"l2update","product_id":"BTC-USD","changes":[["sell","54407.03","0.01690000"]],"time":"2021-04-28T15:27:03.350354Z"}
{"type":"l2update","product_id":"BTC-USD","changes":[["sell","54400.77","0.09191046"]],"time":"2021-04-28T15:27:03.366641Z"}
{"type":"l2update","product_id":"BTC-USD","changes":[["sell","54401.08","0.08000000"]],"time":"2021-04-28T15:27:03.374031Z"}
{"type":"l2update","product_id":"BTC-USD","changes":[["sell","54372.77","0.82596785"]],"time":"2021-04-28T15:27:03.382226Z"}
{"type":"l2update","product_id":"BTC-USD","changes":[["buy","54371.95","0.00000000"]],"time":"2021-04-28T15:27:03.388838Z"}
{"type":"l2update","product_id":"BTC-USD","changes":[["buy","54367.18","0.00000000"]],"time":"2021-04-28T15:27:03.392056Z"}
{"type":"l2update","product_id":"BTC-USD","changes":[["buy","54372.76","2.56256647"]],"time":"2021-04-28T15:27:03.393985Z"}
{"type":"l2update","product_id":"BTC-USD","changes":[["buy","54370.62","0.00000000"]],"time":"2021-04-28T15:27:03.395195Z"}
{"type":"l2update","product_id":"BTC-USD","changes":[["buy","54328.91","0.19000000"]],"time":"2021-04-28T15:27:03.398361Z"}
{"type":"l2update","product_id":"BTC-USD","changes":[["buy","54372.76","2.47061001"]],"time":"2021-04-28T15:27:03.399737Z"}
{"type":"l2update","product_id":"BTC-USD","changes":[["buy","54369.36","0.01690000"]],"time":"2021-04-28T15:27:03.400907Z"}
{"type":"l2update","product_id":"BTC-USD","changes":[["buy","54361.71","0.10000000"]],"time":"2021-04-28T15:27:03.401554Z"}
{"type":"l2update","product_id":"BTC-USD","changes":[["sell","54528.49","0.00000000"]],"time":"2021-04-28T15:27:03.405834Z"}
{"type":"l2update","product_id":"BTC-USD","changes":[["buy","54368.60","0.30000000"]],"time":"2021-04-28T15:27:03.407874Z"}
{"type":"l2update","product_id":"BTC-USD","changes":[["sell","54516.69","0.01000000"]],"time":"2021-04-28T15:27:03.412176Z"}
{"type":"l2update","product_id":"BTC-USD","changes":[["sell","54511.01","0.01000000"]],"time":"2021-04-28T15:27:03.415880Z"}
{"type":"l2update","product_id":"BTC-USD","changes":[["buy","54158.90","0.00000000"]],"time":"2021-04-28T15:27:03.422100Z"}
{"type":"l2update","product_id":"BTC-USD","changes":[["buy","54369.32","0.09196362"]],"time":"2021-04-28T15:27:03.431818Z"}
{"type":"l2update","product_id":"BTC-USD","changes":[["sell","54931.65","0.00000000"]],"time":"2021-04-28T15:27:03.440188Z"}
{"type":"l2update","product_id":"BTC-USD","changes":[["buy","54221.35","0.01000000"]],"time":"2021-04-28T15:27:03.443461Z"}
{"type":"l2update","product_id":"BTC-USD","changes":[["sell","54372.77","0.83201606"]],"time":"2021-04-28T15:27:03.459633Z"}
{"type":"l2update","product_id":"BTC-USD","changes":[["sell","54543.10","0.00000000"]],"time":"2021-04-28T15:27:03.498187Z"}
{"type":"l2update","product_id":"BTC-USD","changes":[["buy","54237.96","0.00000000"]],"time":"2021-04-28T15:27:03.508757Z"}
{"type":"l2update","product_id":"BTC-USD","changes":[["sell","54565.64","0.01000000"]],"time":"2021-04-28T15:27:03.510524Z"}
{"type":"l2update","product_id":"BTC-USD","changes":[["buy","54216.72","0.01000000"]],"time":"2021-04-28T15:27:03.531327Z"}
{"type":"l2update","product_id":"BTC-USD","changes":[["buy","54372.76","2.47368408"]],"time":"2021-04-28T15:27:03.563414Z"}
{"type":"l2update","product_id":"BTC-USD","changes":[["buy","54328.91","0.00000000"]],"time":"2021-04-28T15:27:03.569937Z"}
{"type":"l2update","product_id":"BTC-USD","changes":[["sell","54446.13","0.00000000"]],"time":"2021-04-28T15:27:03.587392Z"}
{"type":"l2update","product_id":"BTC-USD","changes":[["sell","54446.10","0.00000000"]],"time":"2021-04-28T15:27:03.602079Z"}
{"type":"l2update","product_id":"BTC-USD","changes":[["buy","54368.26","0.00000000"]],"time":"2021-04-28T15:27:03.609170Z"}
{"type":"l2update","product_id":"BTC-USD","changes":[["sell","54411.22","0.00000000"]],"time":"2021-04-28T15:27:03.612203Z"}
{"type":"l2update","product_id":"BTC-USD","changes":[["buy","53845.18","0.00000000"]],"time":"2021-04-28T15:27:03.617101Z"}
{"type":"l2update","product_id":"BTC-USD","changes":[["buy","53312.44","0.00000000"]],"time":"2021-04-28T15:27:03.617101Z"}
{"type":"l2update","product_id":"BTC-USD","changes":[["buy","54368.60","0.00000000"]],"time":"2021-04-28T15:27:03.620205Z"}
{"type":"l2update","product_id":"BTC-USD","changes":[["buy","54372.76","2.26368408"]],"time":"2021-04-28T15:27:03.622797Z"}
{"type":"l2update","product_id":"BTC-USD","changes":[["buy","54366.63","0.30000000"]],"time":"2021-04-28T15:27:03.630218Z"}